<?xml version="1.0" encoding="utf-8"?>
<!-- =================================================================================== -->
<!-- |    This document was autogenerated by xacro from thormang3.xacro                | -->
<!-- |    EDITING THIS FILE BY HAND IS NOT RECOMMENDED                                 | -->
<!-- =================================================================================== -->
<!-- Revolute-Revolute Manipulator -->
<robot name="thormang3">
  <!-- ros_control plugin -->
  <gazebo>
    <plugin filename="libgazebo_ros_control.so" name="gazebo_ros_control">
      <robotNamespace>/thormang3</robotNamespace>
      <robotSimType>gazebo_ros_control/DefaultRobotHWSim</robotSimType>
    </plugin>
  </gazebo>
  <gazebo>
    <plugin filename="libgazebo_ros_p3d.so" name="ground_truth">
      <frameName>map</frameName>
      <bodyName>base</bodyName>
      <topicName>odom</topicName>
      <updateRate>100.0</updateRate>
    </plugin>
  </gazebo>
  
  <!-- World -->
  <gazebo reference="world">
  </gazebo>
  <!-- Base -->
  <gazebo reference="base">
  </gazebo>
  <!-- Body-->
  <gazebo reference="base">
    <mu1>0.2</mu1>
    <mu2>0.2</mu2>
    <material>Gazebo/Grey</material>
  </gazebo>
  <gazebo reference="chest_link">
    <mu1>0.2</mu1>
    <mu2>0.2</mu2>
    <material>Gazebo/Grey</material>
  </gazebo>

  <!-- Left Leg -->
  <gazebo reference="l_leg_hip_y_link">
    <mu1>0.2</mu1>
    <mu2>0.2</mu2>
    <material>Gazebo/Grey</material>
  </gazebo>
  <gazebo reference="l_leg_hip_r_link">
    <mu1>0.2</mu1>
    <mu2>0.2</mu2>
    <material>Gazebo/Grey</material>
  </gazebo>
  <gazebo reference="l_leg_hip_p_link">
    <mu1>0.2</mu1>
    <mu2>0.2</mu2>
    <material>Gazebo/Grey</material>
  </gazebo>
  <gazebo reference="l_leg_kn_p_link">
    <mu1>0.2</mu1>
    <mu2>0.2</mu2>
    <material>Gazebo/Grey</material>
  </gazebo>
  <gazebo reference="l_leg_an_p_link">
    <mu1>0.2</mu1>
    <mu2>0.2</mu2>
    <material>Gazebo/Grey</material>
  </gazebo>
  <gazebo reference="l_leg_an_r_link">
    <mu1>0.2</mu1>
    <mu2>0.2</mu2>
    <material>Gazebo/Grey</material>
  </gazebo>
  <gazebo reference="l_leg_foot_link">
    <kp>100000.0</kp>
    <kd>100.0</kd>
    <mu1>1.5</mu1>
    <mu2>1.5</mu2>
    <fdir1>1 0 0</fdir1>
    <maxVel>1.0</maxVel>
    <minDepth>0.0</minDepth>
    <material>Gazebo/Grey</material>
  </gazebo>
  <!-- Right Leg -->
  <gazebo reference="r_leg_hip_y_link">
    <mu1>0.2</mu1>
    <mu2>0.2</mu2>
    <material>Gazebo/Grey</material>
  </gazebo>
  <gazebo reference="r_leg_hip_r_link">
    <mu1>0.2</mu1>
    <mu2>0.2</mu2>
    <material>Gazebo/Grey</material>
  </gazebo>
  <gazebo reference="r_leg_hip_p_link">
    <mu1>0.2</mu1>
    <mu2>0.2</mu2>
    <material>Gazebo/Grey</material>
  </gazebo>
  <gazebo reference="r_leg_kn_p_link">
    <mu1>0.2</mu1>
    <mu2>0.2</mu2>
    <material>Gazebo/Grey</material>
  </gazebo>
  <gazebo reference="r_leg_an_p_link">
    <mu1>0.2</mu1>
    <mu2>0.2</mu2>
    <material>Gazebo/Grey</material>
  </gazebo>
  <gazebo reference="r_leg_an_r_link">
    <mu1>0.2</mu1>
    <mu2>0.2</mu2>
    <material>Gazebo/Grey</material>
  </gazebo>
  <gazebo reference="r_leg_foot_link">
    <kp>100000.0</kp>
    <kd>100.0</kd>
    <mu1>1.5</mu1>
    <mu2>1.5</mu2>
    <fdir1>1 0 0</fdir1>
    <maxVel>1.0</maxVel>
    <minDepth>0.0</minDepth>
    <material>Gazebo/Grey</material>
  </gazebo>
  <material name="black">
    <color rgba="0.0 0.0 0.0 1.0"/>
  </material>
  <material name="blue">
    <color rgba="0.0 0.0 0.8 1.0"/>
  </material>
  <material name="green">
    <color rgba="0.0 0.8 0.0 1.0"/>
  </material>
  <material name="grey">
    <color rgba="0.2 0.2 0.2 1.0"/>
  </material>
  <material name="orange">
    <color rgba="1.0 0.423529411765 0.0392156862745 1.0"/>
  </material>
  <material name="brown">
    <color rgba="0.870588235294 0.811764705882 0.764705882353 1.0"/>
  </material>
  <material name="red">
    <color rgba="0.8 0.0 0.0 1.0"/>
  </material>
  <material name="white">
    <color rgba="1.0 1.0 1.0 1.0"/>
  </material>
  <!-- Used for fixing robot -->
  <!--
  <link name="world">
  </link>

  <joint name="world_fixed" type="fixed">
    <origin xyz="0 0 0" rpy="0 0 0"/>
    <parent link="world"/>
    <child link="base"/>
  </joint>

  <link name="base">
  </link>

  <joint name="base_fixed" type="fixed">
    <origin xyz="0 0 0.723" rpy="0 0 0"/>
    <parent link="base"/>
    <child link="base"/>
  </joint>
-->
  <!-- pelvis_link -->
  <link name="base">
    <collision>
      <origin rpy="0 0 0" xyz="-0.01 0 0.07"/>
      <geometry>
        <box size="0.2 0.25 0.17"/>
      </geometry>
    </collision>
    <visual>
      <origin rpy="0 0 0" xyz="0 0 0"/>
      <geometry>
        <mesh filename="package://thormang3_description/meshes/robotis_pelvis_link.stl" scale="0.001 0.001 0.001"/>
      </geometry>
      <material name="grey"/>
    </visual>
    <inertial>
      <origin rpy="0 0 0" xyz="-0.011 0.000 0.058"/>
      <mass value="6.869"/>
      <inertia ixx="1.0" ixy="0.0" ixz="0.0" iyy="1.0" iyz="0.0" izz="1.0"/>
      <!--<inertia ixx="0.03603" ixy="0.0" ixz="0.00016" iyy="0.02210" iyz="0.0" izz="0.03830" />-->
    </inertial>
  </link>
  
  <!-- left hip yaw joint -->
  <joint name="l_leg_hip_y" type="revolute">
    <axis xyz="0 0 -1"/>
    <origin rpy="0 0 0" xyz="0.0 0.093 -0.018"/>
    <parent link="base"/>
    <child link="l_leg_hip_y_link"/>
    <limit effort="1000" lower="-1.4137166943" upper="1.4137166943" velocity="6.5"/>
    <dynamics damping="0.1" friction="0.0"/>
  </joint>
  <transmission name="l_leg_hip_y_tran">
    <type>transmission_interface/SimpleTransmission</type>
    <joint name="l_leg_hip_y">
      <hardwareInterface>EffortJointInterface</hardwareInterface>
    </joint>
    <actuator name="l_leg_hip_y_motor">
      <hardwareInterface>EffortJointInterface</hardwareInterface>
      <mechanicalReduction>1</mechanicalReduction>
    </actuator>
  </transmission>
  <!-- left hip yaw link -->
  <link name="l_leg_hip_y_link">
    <collision>
      <origin rpy="0 0 0" xyz="-0.01 0 -0.05"/>
      <geometry>
        <box size="0.17 0.07 0.1"/>
      </geometry>
    </collision>
    <visual>
      <origin rpy="0 0 0" xyz="0 0 0"/>
      <geometry>
        <mesh filename="package://thormang3_description/meshes/robotis_l_leg_hip_y_link.stl" scale="0.001 0.001 0.001"/>
      </geometry>
      <material name="grey"/>
    </visual>
    <inertial>
      <origin rpy="0 0 0" xyz="0.012 0.000 -0.025"/>
      <mass value="0.243"/>
      <inertia ixx="1.0" ixy="0.0" ixz="0.0" iyy="1.0" iyz="0.0" izz="1.0"/>
      <!-- <inertia ixx="0.00024" ixy="0.0" ixz="0.0" iyy="0.00101" iyz="0.0" izz="0.00092" /> -->
    </inertial>
  </link>
  <!-- left hip roll joint -->
  <joint name="l_leg_hip_r" type="revolute">
    <axis xyz="-1 0 0"/>
    <origin rpy="0 0 0" xyz="0.057 0.0 -0.075"/>
    <parent link="l_leg_hip_y_link"/>
    <child link="l_leg_hip_r_link"/>
    <limit effort="1000" lower="-0.6283185308" upper="0.9424777962" velocity="6.5"/>
    <dynamics damping="0.1" friction="0.0"/>
  </joint>
  <transmission name="l_leg_hip_r_tran">
    <type>transmission_interface/SimpleTransmission</type>
    <joint name="l_leg_hip_r">
      <hardwareInterface>EffortJointInterface</hardwareInterface>
    </joint>
    <actuator name="l_leg_hip_r_motor">
      <hardwareInterface>EffortJointInterface</hardwareInterface>
      <mechanicalReduction>1</mechanicalReduction>
    </actuator>
  </transmission>
  <!-- left hip roll link -->
  <link name="l_leg_hip_r_link">
    <!--
    	  <collision>
      	    <origin xyz="-0.057 0 0" rpy="0 0 0"/>
      	    <geometry>
              <box size="0.01 0.01 0.01" />
      	    </geometry>
    	  </collision>
-->
    <visual>
      <origin rpy="0 0 0" xyz="0 0 0"/>
      <geometry>
        <mesh filename="package://thormang3_description/meshes/robotis_l_leg_hip_r_link.stl" scale="0.001 0.001 0.001"/>
      </geometry>
      <material name="grey"/>
    </visual>
    <inertial>
      <origin rpy="0 0 0" xyz="-0.068 0.000 0.000"/>
      <mass value="1.045"/>
      <inertia ixx="1.0" ixy="0.0" ixz="0.0" iyy="1.0" iyz="0.0" izz="1.0"/>
      <!-- <inertia ixx="0.00056" ixy="0.0" ixz="0.0" iyy="0.00168" iyz="0.0" izz="0.00171" /> -->
    </inertial>
  </link>
  <!-- left hip pitch joint -->
  <joint name="l_leg_hip_p" type="revolute">
    <axis xyz="0 1 0"/>
    <origin rpy="0 0 0" xyz="-0.057 0.033 0.0"/>
    <parent link="l_leg_hip_r_link"/>
    <child link="l_leg_hip_p_link"/>
    <limit effort="1000" lower="-1.2566370616" upper="1.2566370616" velocity="6.5"/>
    <dynamics damping="0.1" friction="0.0"/>
  </joint>
  <transmission name="l_leg_hip_p_tran">
    <type>transmission_interface/SimpleTransmission</type>
    <joint name="l_leg_hip_p">
      <hardwareInterface>EffortJointInterface</hardwareInterface>
    </joint>
    <actuator name="l_leg_hip_p_motor">
      <hardwareInterface>EffortJointInterface</hardwareInterface>
      <mechanicalReduction>1</mechanicalReduction>
    </actuator>
  </transmission>
  <!-- left hip pitch link -->
  <link name="l_leg_hip_p_link">
    <collision>
      <origin rpy="0 0 0" xyz="0 -0.005 -0.145"/>
      <geometry>
        <box size="0.11 0.16 0.33"/>
      </geometry>
    </collision>
    <visual>
      <origin rpy="0 0 0" xyz="0 0 0"/>
      <geometry>
        <mesh filename="package://thormang3_description/meshes/robotis_l_leg_hip_p_link.stl" scale="0.001 0.001 0.001"/>
      </geometry>
      <material name="grey"/>
    </visual>
    <inertial>
      <origin rpy="0 0 0" xyz="0.022 -0.007 -0.168"/>
      <mass value="3.095"/>
      <inertia ixx="1.0" ixy="0.0" ixz="0.0" iyy="1.0" iyz="0.0" izz="1.0"/>
      <!-- <inertia ixx="0.04328" ixy="0.00028" ixz="0.00288" iyy="0.04042" iyz="-0.00202" izz="0.00560" /> -->
    </inertial>
  </link>
  <!-- left knee pitch joint -->
  <joint name="l_leg_kn_p" type="revolute">
    <axis xyz="0 1 0"/>
    <origin rpy="0 0 0" xyz="0.0 0.06 -0.3"/>
    <parent link="l_leg_hip_p_link"/>
    <child link="l_leg_kn_p_link"/>
    <limit effort="1000" lower="-0.3141592654" upper="2.1991148578" velocity="6.5"/>
    <dynamics damping="0.1" friction="0.0"/>
  </joint>
  <transmission name="l_leg_kn_p_tran">
    <type>transmission_interface/SimpleTransmission</type>
    <joint name="l_leg_kn_p">
      <hardwareInterface>EffortJointInterface</hardwareInterface>
    </joint>
    <actuator name="l_leg_kn_p_motor">
      <hardwareInterface>EffortJointInterface</hardwareInterface>
      <mechanicalReduction>1</mechanicalReduction>
    </actuator>
  </transmission>
  <!-- left knee pitch link -->
  <link name="l_leg_kn_p_link">
    <collision>
      <origin rpy="0 0 0" xyz="0.01 -0.065 -0.145"/>
      <geometry>
        <box size="0.11 0.16 0.33"/>
      </geometry>
    </collision>
    <visual>
      <origin rpy="0 0 0" xyz="0 0 0"/>
      <geometry>
        <mesh filename="package://thormang3_description/meshes/robotis_l_leg_kn_p_link.stl" scale="0.001 0.001 0.001"/>
      </geometry>
      <material name="grey"/>
    </visual>
    <inertial>
      <origin rpy="0 0 0" xyz="-0.002 -0.066 -0.183"/>
      <mass value="2.401"/>
      <inertia ixx="1.0" ixy="0.0" ixz="0.0" iyy="1.0" iyz="0.0" izz="1.0"/>
      <!-- <inertia ixx="0.01971" ixy="0.00031" ixz="-0.00294" iyy="0.01687" iyz="0.00140" izz="0.00574" /> -->
    </inertial>
  </link>
  <!-- left ankle pitch joint -->
  <joint name="l_leg_an_p" type="revolute">
    <axis xyz="0 -1 0"/>
    <origin rpy="0 0 0" xyz="-0.0 -0.06 -0.3"/>
    <parent link="l_leg_kn_p_link"/>
    <child link="l_leg_an_p_link"/>
    <limit effort="1000" lower="-1.4137166943" upper="1.4137166943" velocity="6.5"/>
    <dynamics damping="0.1" friction="0.0"/>
  </joint>
  <transmission name="l_leg_an_p_tran">
    <type>transmission_interface/SimpleTransmission</type>
    <joint name="l_leg_an_p">
      <hardwareInterface>EffortJointInterface</hardwareInterface>
    </joint>
    <actuator name="l_leg_an_p_motor">
      <hardwareInterface>EffortJointInterface</hardwareInterface>
      <mechanicalReduction>1</mechanicalReduction>
    </actuator>
  </transmission>
  <!-- left ankle pitch link -->
  <link name="l_leg_an_p_link">
    <!--
    	  <collision>
      	    <origin xyz="0 0 0" rpy="0 0 0"/>
      	    <geometry>
              <box size="0.01 0.01 0.01" />
      	    </geometry>
    	  </collision>
-->
    <visual>
      <origin rpy="0 0 0" xyz="0 0 0"/>
      <geometry>
        <mesh filename="package://thormang3_description/meshes/robotis_l_leg_an_p_link.stl" scale="0.001 0.001 0.001"/>
      </geometry>
      <material name="grey"/>
    </visual>
    <inertial>
      <origin rpy="0 0 0" xyz="-0.011 -0.033 0.000"/>
      <mass value="1.045"/>
      <inertia ixx="1.0" ixy="0.0" ixz="0.0" iyy="1.0" iyz="0.0" izz="1.0"/>
      <!-- <inertia ixx="0.00056" ixy="0.0" ixz="0.0" iyy="0.00168" iyz="0.0" izz="0.00171" /> -->
    </inertial>
  </link>
  <!-- left ankle roll joint -->
  <joint name="l_leg_an_r" type="revolute">
    <axis xyz="1 0 0"/>
    <origin rpy="0 0 0" xyz="0.057 -0.033 0.0"/>
    <parent link="l_leg_an_p_link"/>
    <child link="l_leg_an_r_link"/>
    <limit effort="1000" lower="-1.570796327" upper="1.2566370616" velocity="6.5"/>
    <dynamics damping="0.1" friction="0.0"/>
  </joint>
  <transmission name="l_leg_an_r_tran">
    <type>transmission_interface/SimpleTransmission</type>
    <joint name="l_leg_an_r">
      <hardwareInterface>EffortJointInterface</hardwareInterface>
    </joint>
    <actuator name="l_leg_an_r_motor">
      <hardwareInterface>EffortJointInterface</hardwareInterface>
      <mechanicalReduction>1</mechanicalReduction>
    </actuator>
  </transmission>
  <!-- left ankle roll link -->
  <link name="l_leg_an_r_link">
    <collision>
      <origin rpy="0 0 0" xyz="-0.067 0 -0.02"/>
      <geometry>
        <box size="0.17 0.06 0.12"/>
      </geometry>
    </collision>
    <visual>
      <origin rpy="0 0 0" xyz="0 0 0"/>
      <geometry>
        <mesh filename="package://thormang3_description/meshes/robotis_l_leg_an_r_link.stl" scale="0.001 0.001 0.001"/>
      </geometry>
      <material name="grey"/>
    </visual>
    <inertial>
      <origin rpy="0 0 0" xyz="-0.070 0.000 -0.048"/>
      <mass value="0.223"/>
      <inertia ixx="1.0" ixy="0.0" ixz="0.0" iyy="1.0" iyz="0.0" izz="1.0"/>
      <!-- <inertia ixx="0.00022" ixy="0.0" ixz="-0.00001" iyy="0.00099" iyz="0.0" izz="0.00091" /> -->
    </inertial>
  </link>
  <!-- left ft joint -->
  <joint name="l_leg_ft" type="fixed">
    <origin rpy="0 0 0" xyz="-0.057 0.0 -0.087"/>
    <parent link="l_leg_an_r_link"/>
    <child link="l_leg_foot_link"/>
  </joint>
  <!-- left foot link -->
  <link name="l_leg_foot_link">
    <collision>
      <origin rpy="0 0 0" xyz="0 0.014 -0.02"/>
      <geometry>
        <box size="0.22 0.15 0.015"/>
      </geometry>
    </collision>
    <visual>
      <origin rpy="0 0 0" xyz="0 0 0"/>
      <geometry>
        <mesh filename="package://thormang3_description/meshes/robotis_l_leg_foot.stl" scale="0.001 0.001 0.001"/>
      </geometry>
      <material name="grey"/>
    </visual>
    <inertial>
      <origin rpy="0 0 0" xyz="0.000 0.009 -0.013"/>
      <mass value="1.689"/>
      <inertia ixx="1.0" ixy="0.0" ixz="0.0" iyy="1.0" iyz="0.0" izz="1.0"/>
      <!-- <inertia ixx="0.00219" ixy="0.0" ixz="0.0" iyy="0.00433" iyz="0.00011" izz="0.00609" /> -->
    </inertial>
  </link>

  <!-- right hip yaw joint -->
  <joint name="r_leg_hip_y" type="revolute">
    <axis xyz="0 0 -1"/>
    <origin rpy="0 0 0" xyz="0.0 -0.093 -0.018"/>
    <parent link="base"/>
    <child link="r_leg_hip_y_link"/>
    <limit effort="1000" lower="-1.4137166943" upper="1.4137166943" velocity="6.5"/>
    <dynamics damping="0.1" friction="0.0"/>
  </joint>
  <transmission name="r_leg_hip_y_tran">
    <type>transmission_interface/SimpleTransmission</type>
    <joint name="r_leg_hip_y">
      <hardwareInterface>EffortJointInterface</hardwareInterface>
    </joint>
    <actuator name="r_leg_hip_y_motor">
      <hardwareInterface>EffortJointInterface</hardwareInterface>
      <mechanicalReduction>1</mechanicalReduction>
    </actuator>
  </transmission>
  <!-- right hip yaw link -->
  <link name="r_leg_hip_y_link">
    <collision>
      <origin rpy="0 0 0" xyz="-0.01 0 -0.05"/>
      <geometry>
        <box size="0.17 0.07 0.1"/>
      </geometry>
    </collision>
    <visual>
      <origin rpy="0 0 0" xyz="0 0 0"/>
      <geometry>
        <mesh filename="package://thormang3_description/meshes/robotis_r_leg_hip_y_link.stl" scale="0.001 0.001 0.001"/>
      </geometry>
      <material name="grey"/>
    </visual>
    <inertial>
      <origin rpy="0 0 0" xyz="-0.012 0.000 -0.025"/>
      <mass value="0.243"/>
      <inertia ixx="1.0" ixy="0.0" ixz="0.0" iyy="1.0" iyz="0.0" izz="1.0"/>
      <!-- <inertia ixx="0.00024" ixy="0.0" ixz="0.0" iyy="0.00101" iyz="0.0" izz="0.00092" /> -->
    </inertial>
  </link>
  <!-- right hip roll joint -->
  <joint name="r_leg_hip_r" type="revolute">
    <axis xyz="-1 0 0"/>
    <origin rpy="0 0 0" xyz="0.057 0.0 -0.075"/>
    <parent link="r_leg_hip_y_link"/>
    <child link="r_leg_hip_r_link"/>
    <limit effort="1000" lower="-0.9424777962" upper="0.6283185308" velocity="6.5"/>
    <dynamics damping="0.1" friction="0.0"/>
  </joint>
  <transmission name="r_leg_hip_r_tran">
    <type>transmission_interface/SimpleTransmission</type>
    <joint name="r_leg_hip_r">
      <hardwareInterface>EffortJointInterface</hardwareInterface>
    </joint>
    <actuator name="r_leg_hip_r_motor">
      <hardwareInterface>EffortJointInterface</hardwareInterface>
      <mechanicalReduction>1</mechanicalReduction>
    </actuator>
  </transmission>
  <!-- right hip roll link -->
  <link name="r_leg_hip_r_link">
    <!--
    	  <collision>
      	    <origin xyz="0 0 0" rpy="0 0 0"/>
      	    <geometry>
              <box size="0.01 0.01 0.01" />
      	    </geometry>
    	  </collision>
-->
    <visual>
      <origin rpy="0 0 0" xyz="0 0 0"/>
      <geometry>
        <mesh filename="package://thormang3_description/meshes/robotis_r_leg_hip_r_link.stl" scale="0.001 0.001 0.001"/>
      </geometry>
      <material name="grey"/>
    </visual>
    <inertial>
      <origin rpy="0 0 0" xyz="-0.068 0.000 0.000"/>
      <mass value="1.045"/>
      <inertia ixx="1.0" ixy="0.0" ixz="0.0" iyy="1.0" iyz="0.0" izz="1.0"/>
      <!-- <inertia ixx="0.00056" ixy="0.0" ixz="0.0" iyy="0.00168" iyz="0.0" izz="0.00171" /> -->
    </inertial>
  </link>
  <!-- right hip pitch joint -->
  <joint name="r_leg_hip_p" type="revolute">
    <axis xyz="0 -1 0"/>
    <origin rpy="0 0 0" xyz="-0.057 -0.033 0.0"/>
    <parent link="r_leg_hip_r_link"/>
    <child link="r_leg_hip_p_link"/>
    <limit effort="1000" lower="-1.2566370616" upper="1.2566370616" velocity="6.5"/>
    <dynamics damping="0.1" friction="0.0"/>
  </joint>
  <transmission name="r_leg_hip_p_tran">
    <type>transmission_interface/SimpleTransmission</type>
    <joint name="r_leg_hip_p">
      <hardwareInterface>EffortJointInterface</hardwareInterface>
    </joint>
    <actuator name="r_leg_hip_p_motor">
      <hardwareInterface>EffortJointInterface</hardwareInterface>
      <mechanicalReduction>1</mechanicalReduction>
    </actuator>
  </transmission>
  <!-- right hip pitch link -->
  <link name="r_leg_hip_p_link">
    <collision>
      <origin rpy="0 0 0" xyz="0 0.005 -0.145"/>
      <geometry>
        <box size="0.11 0.16 0.33"/>
      </geometry>
    </collision>
    <visual>
      <origin rpy="0 0 0" xyz="0 0 0"/>
      <geometry>
        <mesh filename="package://thormang3_description/meshes/robotis_r_leg_hip_p_link.stl" scale="0.001 0.001 0.001"/>
      </geometry>
      <material name="grey"/>
    </visual>
    <inertial>
      <origin rpy="0 0 0" xyz="0.022 0.007 -0.168"/>
      <mass value="3.095"/>
      <inertia ixx="1.0" ixy="0.0" ixz="0.0" iyy="1.0" iyz="0.0" izz="1.0"/>
      <!-- <inertia ixx="0.04328" ixy="-0.00027" ixz="0.00286" iyy="0.04042" iyz="-0.00202" izz="0.00560" /> -->
    </inertial>
  </link>
  <!-- right knee pitch joint -->
  <joint name="r_leg_kn_p" type="revolute">
    <axis xyz="0 -1 0"/>
    <origin rpy="0 0 0" xyz="0.0 -0.06 -0.3"/>
    <parent link="r_leg_hip_p_link"/>
    <child link="r_leg_kn_p_link"/>
    <limit effort="1000" lower="-2.1991148578" upper="0.3141592654" velocity="6.5"/>
    <dynamics damping="0.1" friction="0.0"/>
  </joint>
  <transmission name="r_leg_kn_p_tran">
    <type>transmission_interface/SimpleTransmission</type>
    <joint name="r_leg_kn_p">
      <hardwareInterface>EffortJointInterface</hardwareInterface>
    </joint>
    <actuator name="r_leg_kn_p_motor">
      <hardwareInterface>EffortJointInterface</hardwareInterface>
      <mechanicalReduction>1</mechanicalReduction>
    </actuator>
  </transmission>
  <!-- right knee pitch link -->
  <link name="r_leg_kn_p_link">
    <collision>
      <origin rpy="0 0 0" xyz="0.01 0.065 -0.145"/>
      <geometry>
        <box size="0.11 0.16 0.33"/>
      </geometry>
    </collision>
    <visual>
      <origin rpy="0 0 0" xyz="0 0 0"/>
      <geometry>
        <mesh filename="package://thormang3_description/meshes/robotis_r_leg_kn_p_link.stl" scale="0.001 0.001 0.001"/>
      </geometry>
      <material name="grey"/>
    </visual>
    <inertial>
      <origin rpy="0 0 0" xyz="-0.002 0.066 -0.183"/>
      <mass value="2.401"/>
      <inertia ixx="1.0" ixy="0.0" ixz="0.0" iyy="1.0" iyz="0.0" izz="1.0"/>
      <!-- <inertia ixx="0.01971" ixy="-0.00031" ixz="-0.00294" iyy="0.01687" iyz="-0.00140" izz="0.00574" /> -->
    </inertial>
  </link>
  <!-- right ankle pitch joint -->
  <joint name="r_leg_an_p" type="revolute">
    <axis xyz="0 1 0"/>
    <origin rpy="0 0 0" xyz="-0.0 0.06 -0.3"/>
    <parent link="r_leg_kn_p_link"/>
    <child link="r_leg_an_p_link"/>
    <limit effort="1000" lower="-1.4137166943" upper="1.4137166943" velocity="6.5"/>
    <dynamics damping="0.1" friction="0.0"/>
  </joint>
  <transmission name="r_leg_an_p_tran">
    <type>transmission_interface/SimpleTransmission</type>
    <joint name="r_leg_an_p">
      <hardwareInterface>EffortJointInterface</hardwareInterface>
    </joint>
    <actuator name="r_leg_an_p_motor">
      <hardwareInterface>EffortJointInterface</hardwareInterface>
      <mechanicalReduction>1</mechanicalReduction>
    </actuator>
  </transmission>
  <!-- right ankle pitch link -->
  <link name="r_leg_an_p_link">
    <!--
    	  <collision>
      	    <origin xyz="0 0 0" rpy="0 0 0"/>
      	    <geometry>
              <box size="0.01 0.01 0.01" />
      	    </geometry>
    	  </collision>
-->
    <visual>
      <origin rpy="0 0 0" xyz="0 0 0"/>
      <geometry>
        <mesh filename="package://thormang3_description/meshes/robotis_r_leg_an_p_link.stl" scale="0.001 0.001 0.001"/>
      </geometry>
      <material name="grey"/>
    </visual>
    <inertial>
      <origin rpy="0 0 0" xyz="-0.011 0.033 0.000"/>
      <mass value="1.045"/>
      <inertia ixx="1.0" ixy="0.0" ixz="0.0" iyy="1.0" iyz="0.0" izz="1.0"/>
      <!-- <inertia ixx="0.00056" ixy="0.0" ixz="0.0" iyy="0.00168" iyz="0.0" izz="0.00171" /> -->
    </inertial>
  </link>
  <!-- right ankle roll joint -->
  <joint name="r_leg_an_r" type="revolute">
    <axis xyz="1 0 0"/>
    <origin rpy="0 0 0" xyz="0.057 0.033 0.0"/>
    <parent link="r_leg_an_p_link"/>
    <child link="r_leg_an_r_link"/>
    <limit effort="1000" lower="-1.4137166943" upper="1.4137166943" velocity="6.5"/>
    <dynamics damping="0.1" friction="0.0"/>
  </joint>
  <transmission name="r_leg_an_r_tran">
    <type>transmission_interface/SimpleTransmission</type>
    <joint name="r_leg_an_r">
      <hardwareInterface>EffortJointInterface</hardwareInterface>
    </joint>
    <actuator name="r_leg_an_r_motor">
      <hardwareInterface>EffortJointInterface</hardwareInterface>
      <mechanicalReduction>1</mechanicalReduction>
    </actuator>
  </transmission>
  <!-- right ankle roll link -->
  <link name="r_leg_an_r_link">
    <collision>
      <origin rpy="0 0 0" xyz="-0.067 0 -0.02"/>
      <geometry>
        <box size="0.17 0.06 0.12"/>
      </geometry>
    </collision>
    <visual>
      <origin rpy="0 0 0" xyz="0 0 0"/>
      <geometry>
        <mesh filename="package://thormang3_description/meshes/robotis_r_leg_an_r_link.stl" scale="0.001 0.001 0.001"/>
      </geometry>
      <material name="grey"/>
    </visual>
    <inertial>
      <origin rpy="0 0 0" xyz="-0.070 0.000 -0.048"/>
      <mass value="0.223"/>
      <inertia ixx="1.0" ixy="0.0" ixz="0.0" iyy="1.0" iyz="0.0" izz="1.0"/>
      <!-- <inertia ixx="0.00022" ixy="0.0" ixz="-0.00001" iyy="0.00099" iyz="0.0" izz="0.00091" /> -->
    </inertial>
  </link>
  <!-- right ft joint -->
  <joint name="r_leg_ft" type="fixed">
    <origin rpy="0 0 0" xyz="-0.057 0.0 -0.087"/>
    <parent link="r_leg_an_r_link"/>
    <child link="r_leg_foot_link"/>
  </joint>
  <!-- right foot link -->
  <link name="r_leg_foot_link">
    <collision>
      <origin rpy="0 0 0" xyz="0 -0.014 -0.02"/>
      <geometry>
        <box size="0.22 0.15 0.015"/>
      </geometry>
    </collision>
    <visual>
      <origin rpy="0 0 0" xyz="0 0 0"/>
      <geometry>
        <mesh filename="package://thormang3_description/meshes/robotis_r_leg_foot.stl" scale="0.001 0.001 0.001"/>
      </geometry>
      <material name="grey"/>
    </visual>
    <inertial>
      <origin rpy="0 0 0" xyz="0.000 -0.009 -0.013"/>
      <mass value="1.689"/>
      <inertia ixx="1.0" ixy="0.0" ixz="0.0" iyy="1.0" iyz="0.0" izz="1.0"/>
      <!-- <inertia ixx="0.00219" ixy="0.0" ixz="0.0" iyy="0.00433" iyz="-0.00011" izz="0.00609" /> -->
    </inertial>
  </link>
</robot>

